Workbook

Sheet Hoja2
A1: CodPer | B1: CodGra | C1: CodSec | D1: CedAlu | E1: FchInsc | F1: FchNac | G1: SexAlu | H1: LugNac | I1: EntFed | J1: CedRpr | K1: Cédula Limpia | L1: Fecha Limpia | M1: Sexo Limpio | N1: Lugar Nacimiento Limpio | O1: Entidad Federal Limpia
A2: 2025-2026 | B2: 1F | C2: A | D2: 000034914190 | E2: 45922 | F2: =IFERROR(VLOOKUP(TRIM($D2), Hoja4_2!$A$2:$L$10000, 4, 0), "Revisar") -> 41539 | G2: =IFERROR(VLOOKUP(TRIM($D2), Hoja4_2!$A$2:$L$10000, 5, 0), "Revisar") -> FEMENINO | H2: =IFERROR(VLOOKUP(TRIM($D2), Hoja4_2!$A$2:$L$10000, 7, 0), "Revisar") -> MARACAIBO | I2: =IFERROR(VLOOKUP(TRIM($D2), Hoja4_2!$A$2:$L$10000, 9, 0), "Revisar") -> ZU | J2: =IFERROR(VLOOKUP(TRIM($D2), Hoja4_2!$A$2:$L$10000, 12, 0), "Revisar") -> 16080038 | K2: =TEXT(TRIM(D2),"0") -> 34914190 | L2: =IF(F2="Revisar","NULL",CONCATENATE("'",TEXT(F2,"yyyy-mm-dd"),"'")) -> '2013-09-22' | M2: =IF(G2="Revisar","NULL",CONCATENATE("'",MID(G2,1,1),"'")) -> 'F' | N2: =IF(H2="Revisar","NULL",CONCATENATE("'",H2,"'")) -> 'MARACAIBO' | O2: =IF(I2="Revisar","NULL",CONCATENATE("'",I2,"'")) -> 'ZU' | P2: ="UPDATE estudiantes SET fecha_nacimiento="&L2&", sexo="&M2&", lugar_nacimiento="&N2&", entidad_federal="&O2&" WHERE cedula='"&K2&"';" -> UPDATE estudiantes SET fecha_nacimiento='2013-09-22', sexo='F', lugar_nacimiento='MARACAIBO', entidad_federal='ZU' WHERE cedula='34914190';
A3: 2025-2026 | B3: 1F | C3: A | D3: 000035178783 | E3: 45922 | F3: =IFERROR(VLOOKUP(TRIM($D3), Hoja4_2!$A$2:$L$10000, 4, 0), "Revisar") -> 41413 | G3: =IFERROR(VLOOKUP(TRIM($D3), Hoja4_2!$A$2:$L$10000, 5, 0), "Revisar") -> FEMENINO | H3: =IFERROR(VLOOKUP(TRIM($D3), Hoja4_2!$A$2:$L$10000, 7, 0), "Revisar") -> MARACAIBO | I3: =IFERROR(VLOOKUP(TRIM($D3), Hoja4_2!$A$2:$L$10000, 9, 0), "Revisar") -> ZU | J3: =IFERROR(VLOOKUP(TRIM($D3), Hoja4_2!$A$2:$L$10000, 12, 0), "Revisar") -> 21039596 | K3: =TEXT(TRIM(D3),"0") -> 35178783 | L3: =IF(F3="Revisar","NULL",CONCATENATE("'",TEXT(F3,"yyyy-mm-dd"),"'")) -> '2013-05-19' | M3: =IF(G3="Revisar","NULL",CONCATENATE("'",MID(G3,1,1),"'")) -> 'F' | N3: =IF(H3="Revisar","NULL",CONCATENATE("'",H3,"'")) -> 'MARACAIBO' | O3: =IF(I3="Revisar","NULL",CONCATENATE("'",I3,"'")) -> 'ZU' | P3: ="UPDATE estudiantes SET fecha_nacimiento="&L3&", sexo="&M3&", lugar_nacimiento="&N3&", entidad_federal="&O3&" WHERE cedula='"&K3&"';" -> UPDATE estudiantes SET fecha_nacimiento='2013-05-19', sexo='F', lugar_nacimiento='MARACAIBO', entidad_federal='ZU' WHERE cedula='35178783';
A4: 2025-2026 | B4: 1F | C4: A | D4: 000035178802 | E4: 45922 | F4: =IFERROR(VLOOKUP(TRIM($D4), Hoja4_2!$A$2:$L$10000, 4, 0), "Revisar") -> 41492 | G4: =IFERROR(VLOOKUP(TRIM($D4), Hoja4_2!$A$2:$L$10000, 5, 0), "Revisar") -> MASCULINO | H4: =IFERROR(VLOOKUP(TRIM($D4), Hoja4_2!$A$2:$L$10000, 7, 0), "Revisar") -> MARACAIBO | I4: =IFERROR(VLOOKUP(TRIM($D4), Hoja4_2!$A$2:$L$10000, 9, 0), "Revisar") -> ZU | J4: =IFERROR(VLOOKUP(TRIM($D4), Hoja4_2!$A$2:$L$10000, 12, 0), "Revisar") -> 13005173 | K4: =TEXT(TRIM(D4),"0") -> 35178802 | L4: =IF(F4="Revisar","NULL",CONCATENATE("'",TEXT(F4,"yyyy-mm-dd"),"'")) -> '2013-08-06' | M4: =IF(G4="Revisar","NULL",CONCATENATE("'",MID(G4,1,1),"'")) -> 'M' | N4: =IF(H4="Revisar","NULL",CONCATENATE("'",H4,"'")) -> 'MARACAIBO' | O4: =IF(I4="Revisar","NULL",CONCATENATE("'",I4,"'")) -> 'ZU' | P4: ="UPDATE estudiantes SET fecha_nacimiento="&L4&", sexo="&M4&", lugar_nacimiento="&N4&", entidad_federal="&O4&" WHERE cedula='"&K4&"';" -> UPDATE estudiantes SET fecha_nacimiento='2013-08-06', sexo='M', lugar_nacimiento='MARACAIBO', entidad_federal='ZU' WHERE cedula='35178802';
A5: 2025-2026 | B5: 1F | C5: A | D5: 000035182532 | E5: 45922 | F5: =IFERROR(VLOOKUP(TRIM($D5), Hoja4_2!$A$2:$L$10000, 4, 0), "Revisar") -> 41491 | G5: =IFERROR(VLOOKUP(TRIM($D5), Hoja4_2!$A$2:$L$10000, 5, 0), "Revisar") -> FEMENINO | H5: =IFERROR(VLOOKUP(TRIM($D5), Hoja4_2!$A$2:$L$10000, 7, 0), "Revisar") -> MARACAIBO | I5: =IFERROR(VLOOKUP(TRIM($D5), Hoja4_2!$A$2:$L$10000, 9, 0), "Revisar") -> ZU | J5: =IFERROR(VLOOKUP(TRIM($D5), Hoja4_2!$A$2:$L$10000, 12, 0), "Revisar") -> 16016439 | K5: =TEXT(TRIM(D5),"0") -> 35182532 | L5: =IF(F5="Revisar","NULL",CONCATENATE("'",TEXT(F5,"yyyy-mm-dd"),"'")) -> '2013-08-05' | M5: =IF(G5="Revisar","NULL",CONCATENATE("'",MID(G5,1,1),"'")) -> 'F' | N5: =IF(H5="Revisar","NULL",CONCATENATE("'",H5,"'")) -> 'MARACAIBO' | O5: =IF(I5="Revisar","NULL",CONCATENATE("'",I5,"'")) -> 'ZU' | P5: ="UPDATE estudiantes SET fecha_nacimiento="&L5&", sexo="&M5&", lugar_nacimiento="&N5&", entidad_federal="&O5&" WHERE cedula='"&K5&"';" -> UPDATE estudiantes SET fecha_nacimiento='2013-08-05', sexo='F', lugar_nacimiento='MARACAIBO', entidad_federal='ZU' WHERE cedula='35182532';
A6: 2025-2026 | B6: 1F | C6: A | D6: 000036217814 | E6: 45922 | F6: =IFERROR(VLOOKUP(TRIM($D6), Hoja4_2!$A$2:$L$10000, 4, 0), "Revisar") -> 41529 | G6: =IFERROR(VLOOKUP(TRIM($D6), Hoja4_2!$A$2:$L$10000, 5, 0), "Revisar") -> FEMENINO | H6: =IFERROR(VLOOKUP(TRIM($D6), Hoja4_2!$A$2:$L$10000, 7, 0), "Revisar") -> MARACAIBO | I6: =IFERROR(VLOOKUP(TRIM($D6), Hoja4_2!$A$2:$L$10000, 9, 0), "Revisar") -> ZU | J6: =IFERROR(VLOOKUP(TRIM($D6), Hoja4_2!$A$2:$L$10000, 12, 0), "Revisar") -> 20842771 | K6: =TEXT(TRIM(D6),"0") -> 36217814 | L6: =IF(F6="Revisar","NULL",CONCATENATE("'",TEXT(F6,"yyyy-mm-dd"),"'")) -> '2013-09-12' | M6: =IF(G6="Revisar","NULL",CONCATENATE("'",MID(G6,1,1),"'")) -> 'F' | N6: =IF(H6="Revisar","NULL",CONCATENATE("'",H6,"'")) -> 'MARACAIBO' | O6: =IF(I6="Revisar","NULL",CONCATENATE("'",I6,"'")) -> 'ZU' | P6: ="UPDATE estudiantes SET fecha_nacimiento="&L6&", sexo="&M6&", lugar_nacimiento="&N6&", entidad_federal="&O6&" WHERE cedula='"&K6&"';" -> UPDATE estudiantes SET fecha_nacimiento='2013-09-12', sexo='F', lugar_nacimiento='MARACAIBO', entidad_federal='ZU' WHERE cedula='36217814';
A7: 2025-2026 | B7: 1F | C7: A | D7: 000036233626 | E7: 45922 | F7: =IFERROR(VLOOKUP(TRIM($D7), Hoja4_2!$A$2:$L$10000, 4, 0), "Revisar") -> 41524 | G7: =IFERROR(VLOOKUP(TRIM($D7), Hoja4_2!$A$2:$L$10000, 5, 0), "Revisar") -> FEMENINO | H7: =IFERROR(VLOOKUP(TRIM($D7), Hoja4_2!$A$2:$L$10000, 7, 0), "Revisar") -> MARACAIBO | I7: =IFERROR(VLOOKUP(TRIM($D7), Hoja4_2!$A$2:$L$10000, 9, 0), "Revisar") -> ZU | J7: =IFERROR(VLOOKUP(TRIM($D7), Hoja4_2!$A$2:$L$10000, 12, 0), "Revisar") -> 15260609 | K7: =TEXT(TRIM(D7),"0") -> 36233626 | L7: =IF(F7="Revisar","NULL",CONCATENATE("'",TEXT(F7,"yyyy-mm-dd"),"'")) -> '2013-09-07' | M7: =IF(G7="Revisar","NULL",CONCATENATE("'",MID(G7,1,1),"'")) -> 'F' | N7: =IF(H7="Revisar","NULL",CONCATENATE("'",H7,"'")) -> 'MARACAIBO' | O7: =IF(I7="Revisar","NULL",CONCATENATE("'",I7,"'")) -> 'ZU' | P7: ="UPDATE estudiantes SET fecha_nacimiento="&L7&", sexo="&M7&", lugar_nacimiento="&N7&", entidad_federal="&O7&" WHERE cedula='"&K7&"';" -> UPDATE estudiantes SET fecha_nacimiento='2013-09-07', sexo='F', lugar_nacimiento='MARACAIBO', entidad_federal='ZU' WHERE cedula='36233626';
A8: 2025-2026 | B8: 1F | C8: A | D8: 000036380491 | E8: 45922 | F8: =IFERROR(VLOOKUP(TRIM($D8), Hoja4_2!$A$2:$L$10000, 4, 0), "Revisar") -> 41349 | G8: =IFERROR(VLOOKUP(TRIM($D8), Hoja4_2!$A$2:$L$10000, 5, 0), "Revisar") -> FEMENINO | H8: =IFERROR(VLOOKUP(TRIM($D8), Hoja4_2!$A$2:$L$10000, 7, 0), "Revisar") -> MARACAIBO | I8: =IFERROR(VLOOKUP(TRIM($D8), Hoja4_2!$A$2:$L$10000, 9, 0), "Revisar") -> ZU | J8: =IFERROR(VLOOKUP(TRIM($D8), Hoja4_2!$A$2:$L$10000, 12, 0), "Revisar") -> 17634587 | K8: =TEXT(TRIM(D8),"0") -> 36380491 | L8: =IF(F8="Revisar","NULL",CONCATENATE("'",TEXT(F8,"yyyy-mm-dd"),"'")) -> '2013-03-16' | M8: =IF(G8="Revisar","NULL",CONCATENATE("'",MID(G8,1,1),"'")) -> 'F' | N8: =IF(H8="Revisar","NULL",CONCATENATE("'",H8,"'")) -> 'MARACAIBO' | O8: =IF(I8="Revisar","NULL",CONCATENATE("'",I8,"'")) -> 'ZU' | P8: ="UPDATE estudiantes SET fecha_nacimiento="&L8&", sexo="&M8&", lugar_nacimiento="&N8&", entidad_federal="&O8&" WHERE cedula='"&K8&"';" -> UPDATE estudiantes SET fecha_nacimiento='2013-03-16', sexo='F', lugar_nacimiento='MARACAIBO', entidad_federal='ZU' WHERE cedula='36380491';
A9: 2025-2026 | B9: 1F | C9: A | D9: 000036426374 | E9: 45922 | F9: =IFERROR(VLOOKUP(TRIM($D9), Hoja4_2!$A$2:$L$10000, 4, 0), "Revisar") -> 41332 | G9: =IFERROR(VLOOKUP(TRIM($D9), Hoja4_2!$A$2:$L$10000, 5, 0), "Revisar") -> FEMENINO | H9: =IFERROR(VLOOKUP(TRIM($D9), Hoja4_2!$A$2:$L$10000, 7, 0), "Revisar") -> MARACAIBO | I9: =IFERROR(VLOOKUP(TRIM($D9), Hoja4_2!$A$2:$L$10000, 9, 0), "Revisar") -> ZU | J9: =IFERROR(VLOOKUP(TRIM($D9), Hoja4_2!$A$2:$L$10000, 12, 0), "Revisar") -> 29790969 | K9: =TEXT(TRIM(D9),"0") -> 36426374 | L9: =IF(F9="Revisar","NULL",CONCATENATE("'",TEXT(F9,"yyyy-mm-dd"),"'")) -> '2013-02-27' | M9: =IF(G9="Revisar","NULL",CONCATENATE("'",MID(G9,1,1),"'")) -> 'F' | N9: =IF(H9="Revisar","NULL",CONCATENATE("'",H9,"'")) -> 'MARACAIBO' | O9: =IF(I9="Revisar","NULL",CONCATENATE("'",I9,"'")) -> 'ZU' | P9: ="UPDATE estudiantes SET fecha_nacimiento="&L9&", sexo="&M9&", lugar_nacimiento="&N9&", entidad_federal="&O9&" WHERE cedula='"&K9&"';" -> UPDATE estudiantes SET fecha_nacimiento='2013-02-27', sexo='F', lugar_nacimiento='MARACAIBO', entidad_federal='ZU' WHERE cedula='36426374';
A10: 2025-2026 | B10: 1F | C10: A | D10: 000036445996 | E10: 45922 | F10: =IFERROR(VLOOKUP(TRIM($D10), Hoja4_2!$A$2:$L$10000, 4, 0), "Revisar") -> 41614 | G10: =IFERROR(VLOOKUP(TRIM($D10), Hoja4_2!$A$2:$L$10000, 5, 0), "Revisar") -> FEMENINO | H10: =IFERROR(VLOOKUP(TRIM($D10), Hoja4_2!$A$2:$L$10000, 7, 0), "Revisar") -> MARACAIBO | I10: =IFERROR(VLOOKUP(TRIM($D10), Hoja4_2!$A$2:$L$10000, 9, 0), "Revisar") -> ZU | J10: =IFERROR(VLOOKUP(TRIM($D10), Hoja4_2!$A$2:$L$10000, 12, 0), "Revisar") -> 16494712 | K10: =TEXT(TRIM(D10),"0") -> 36445996 | L10: =IF(F10="Revisar","NULL",CONCATENATE("'",TEXT(F10,"yyyy-mm-dd"),"'")) -> '2013-12-06' | M10: =IF(G10="Revisar","NULL",CONCATENATE("'",MID(G10,1,1),"'")) -> 'F' | N10: =IF(H10="Revisar","NULL",CONCATENATE("'",H10,"'")) -> 'MARACAIBO' | O10: =IF(I10="Revisar","NULL",CONCATENATE("'",I10,"'")) -> 'ZU' | P10: ="UPDATE estudiantes SET fecha_nacimiento="&L10&", sexo="&M10&", lugar_nacimiento="&N10&", entidad_federal="&O10&" WHERE cedula='"&K10&"';" -> UPDATE estudiantes SET fecha_nacimiento='2013-12-06', sexo='F', lugar_nacimiento='MARACAIBO', entidad_federal='ZU' WHERE cedula='36445996';
A11: 2025-2026 | B11: 1F | C11: A | D11: 000036523932 | E11: 45922 | F11: =IFERROR(VLOOKUP(TRIM($D11), Hoja4_2!$A$2:$L$10000, 4, 0), "Revisar") -> 41498 | G11: =IFERROR(VLOOKUP(TRIM($D11), Hoja4_2!$A$2:$L$10000, 5, 0), "Revisar") -> MASCULINO | H11: =IFERROR(VLOOKUP(TRIM($D11), Hoja4_2!$A$2:$L$10000, 7, 0), "Revisar") -> MARACAIBO | I11: =IFERROR(VLOOKUP(TRIM($D11), Hoja4_2!$A$2:$L$10000, 9, 0), "Revisar") -> ZU | J11: =IFERROR(VLOOKUP(TRIM($D11), Hoja4_2!$A$2:$L$10000, 12, 0), "Revisar") -> 10432371 | K11: =TEXT(TRIM(D11),"0") -> 36523932 | L11: =IF(F11="Revisar","NULL",CONCATENATE("'",TEXT(F11,"yyyy-mm-dd"),"'")) -> '2013-08-12' | M11: =IF(G11="Revisar","NULL",CONCATENATE("'",MID(G11,1,1),"'")) -> 'M' | N11: =IF(H11="Revisar","NULL",CONCATENATE("'",H11,"'")) -> 'MARACAIBO' | O11: =IF(I11="Revisar","NULL",CONCATENATE("'",I11,"'")) -> 'ZU' | P11: ="UPDATE estudiantes SET fecha_nacimiento="&L11&", sexo="&M11&", lugar_nacimiento="&N11&", entidad_federal="&O11&" WHERE cedula='"&K11&"';" -> UPDATE estudiantes SET fecha_nacimiento='2013-08-12', sexo='M', lugar_nacimiento='MARACAIBO', entidad_federal='ZU' WHERE cedula='36523932';
A12: 2025-2026 | B12: 1F | C12: A | D12: 000036582440 | E12: 45919 | F12: =IFERROR(VLOOKUP(TRIM($D12), Hoja4_2!$A$2:$L$10000, 4, 0), "Revisar") -> 41811 | G12: =IFERROR(VLOOKUP(TRIM($D12), Hoja4_2!$A$2:$L$10000, 5, 0), "Revisar") -> FEMENINO | H12: =IFERROR(VLOOKUP(TRIM($D12), Hoja4_2!$A$2:$L$10000, 7, 0), "Revisar") -> MARACAIBO | I12: =IFERROR(VLOOKUP(TRIM($D12), Hoja4_2!$A$2:$L$10000, 9, 0), "Revisar") -> ZU | J12: =IFERROR(VLOOKUP(TRIM($D12), Hoja4_2!$A$2:$L$10000, 12, 0), "Revisar") -> 17634574 | K12: =TEXT(TRIM(D12),"0") -> 36582440 | L12: =IF(F12="Revisar","NULL",CONCATENATE("'",TEXT(F12,"yyyy-mm-dd"),"'")) -> '2014-06-21' | M12: =IF(G12="Revisar","NULL",CONCATENATE("'",MID(G12,1,1),"'")) -> 'F' | N12: =IF(H12="Revisar","NULL",CONCATENATE("'",H12,"'")) -> 'MARACAIBO' | O12: =IF(I12="Revisar","NULL",CONCATENATE("'",I12,"'")) -> 'ZU' | P12: ="UPDATE estudiantes SET fecha_nacimiento="&L12&", sexo="&M12&", lugar_nacimiento="&N12&", entidad_federal="&O12&" WHERE cedula='"&K12&"';" -> UPDATE estudiantes SET fecha_nacimiento='2014-06-21', sexo='F', lugar_nacimiento='MARACAIBO', entidad_federal='ZU' WHERE cedula='36582440';
A13: 2025-2026 | B13: 1F | C13: A | D13: 000036698493 | E13: 45922 | F13: =IFERROR(VLOOKUP(TRIM($D13), Hoja4_2!$A$2:$L$10000, 4, 0), "Revisar") -> 41503 | G13: =IFERROR(VLOOKUP(TRIM($D13), Hoja4_2!$A$2:$L$10000, 5, 0), "Revisar") -> MASCULINO | H13: =IFERROR(VLOOKUP(TRIM($D13), Hoja4_2!$A$2:$L$10000, 7, 0), "Revisar") -> MARACAIBO | I13: =IFERROR(VLOOKUP(TRIM($D13), Hoja4_2!$A$2:$L$10000, 9, 0), "Revisar") -> ZU | J13: =IFERROR(VLOOKUP(TRIM($D13), Hoja4_2!$A$2:$L$10000, 12, 0), "Revisar") -> 18662136 | K13: =TEXT(TRIM(D13),"0") -> 36698493 | L13: =IF(F13="Revisar","NULL",CONCATENATE("'",TEXT(F13,"yyyy-mm-dd"),"'")) -> '2013-08-17' | M13: =IF(G13="Revisar","NULL",CONCATENATE("'",MID(G13,1,1),"'")) -> 'M' | N13: =IF(H13="Revisar","NULL",CONCATENATE("'",H13,"'")) -> 'MARACAIBO' | O13: =IF(I13="Revisar","NULL",CONCATENATE("'",I13,"'")) -> 'ZU' | P13: ="UPDATE estudiantes SET fecha_nacimiento="&L13&", sexo="&M13&", lugar_nacimiento="&N13&", entidad_federal="&O13&" WHERE cedula='"&K13&"';" -> UPDATE estudiantes SET fecha_nacimiento='2013-08-17', sexo='M', lugar_nacimiento='MARACAIBO', entidad_federal='ZU' WHERE cedula='36698493';
... A63: 2025-2026 | B63: 1F | C63: B | D63: 011322469544 | E63: 45922 | F63: =IFERROR(VLOOKUP(TRIM($D63), Hoja4_2!$A$2:$L$10000, 4, 0), "Revisar") -> 41544 | G63: =IFERROR(VLOOKUP(TRIM($D63), Hoja4_2!$A$2:$L$10000, 5, 0), "Revisar") -> FEMENINO | H63: =IFERROR(VLOOKUP(TRIM($D63), Hoja4_2!$A$2:$L$10000, 7, 0), "Revisar") -> MARACAIBO | I63: =IFERROR(VLOOKUP(TRIM($D63), Hoja4_2!$A$2:$L$10000, 9, 0), "Revisar") -> ZU | J63: =IFERROR(VLOOKUP(TRIM($D63), Hoja4_2!$A$2:$L$10000, 12, 0), "Revisar") -> 22469544 | K63: =TEXT(TRIM(D63),"0") -> 11322469544 | L63: =IF(F63="Revisar","NULL",CONCATENATE("'",TEXT(F63,"yyyy-mm-dd"),"'")) -> '2013-09-27' | M63: =IF(G63="Revisar","NULL",CONCATENATE("'",MID(G63,1,1),"'")) -> 'F' | N63: =IF(H63="Revisar","NULL",CONCATENATE("'",H63,"'")) -> 'MARACAIBO' | O63: =IF(I63="Revisar","NULL",CONCATENATE("'",I63,"'")) -> 'ZU' | P63: ="UPDATE estudiantes SET fecha_nacimiento="&L63&", sexo="&M63&", lugar_nacimiento="&N63&", entidad_federal="&O63&" WHERE cedula='"&K63&"';" -> UPDATE estudiantes SET fecha_nacimiento='2013-09-27', sexo='F', lugar_nacimiento='MARACAIBO', entidad_federal='ZU' WHERE cedula='11322469544';
A64: 2025-2026 | B64: 1F | C64: B | D64: 011323272285 | E64: 46126 | F64: NULL | G64: NULL | H64: NULL | I64: NULL | J64: NULL | K64: =TEXT(TRIM(D64),"0") -> 11323272285 | L64: =IF(F64="Revisar","NULL",CONCATENATE("'",TEXT(F64,"yyyy-mm-dd"),"'")) -> 'NULL' | M64: =IF(G64="Revisar","NULL",CONCATENATE("'",MID(G64,1,1),"'")) -> 'N' | N64: =IF(H64="Revisar","NULL",CONCATENATE("'",H64,"'")) -> 'NULL' | O64: =IF(I64="Revisar","NULL",CONCATENATE("'",I64,"'")) -> 'NULL' | P64: ="UPDATE estudiantes SET fecha_nacimiento="&L64&", sexo="&M64&", lugar_nacimiento="&N64&", entidad_federal="&O64&" WHERE cedula='"&K64&"';" -> UPDATE estudiantes SET fecha_nacimiento='NULL', sexo='N', lugar_nacimiento='NULL', entidad_federal='NULL' WHERE cedula='11323272285';
A65: 2025-2026 | B65: 1F | C65: B | D65: 011325596102 | E65: 45922 | F65: =IFERROR(VLOOKUP(TRIM($D65), Hoja4_2!$A$2:$L$10000, 4, 0), "Revisar") -> 41513 | G65: =IFERROR(VLOOKUP(TRIM($D65), Hoja4_2!$A$2:$L$10000, 5, 0), "Revisar") -> FEMENINO | H65: =IFERROR(VLOOKUP(TRIM($D65), Hoja4_2!$A$2:$L$10000, 7, 0), "Revisar") -> MARACAIBO | I65: =IFERROR(VLOOKUP(TRIM($D65), Hoja4_2!$A$2:$L$10000, 9, 0), "Revisar") -> ZU | J65: =IFERROR(VLOOKUP(TRIM($D65), Hoja4_2!$A$2:$L$10000, 12, 0), "Revisar") -> 25596102 | K65: =TEXT(TRIM(D65),"0") -> 11325596102 | L65: =IF(F65="Revisar","NULL",CONCATENATE("'",TEXT(F65,"yyyy-mm-dd"),"'")) -> '2013-08-27' | M65: =IF(G65="Revisar","NULL",CONCATENATE("'",MID(G65,1,1),"'")) -> 'F' | N65: =IF(H65="Revisar","NULL",CONCATENATE("'",H65,"'")) -> 'MARACAIBO' | O65: =IF(I65="Revisar","NULL",CONCATENATE("'",I65,"'")) -> 'ZU' | P65: ="UPDATE estudiantes SET fecha_nacimiento="&L65&", sexo="&M65&", lugar_nacimiento="&N65&", entidad_federal="&O65&" WHERE cedula='"&K65&"';" -> UPDATE estudiantes SET fecha_nacimiento='2013-08-27', sexo='F', lugar_nacimiento='MARACAIBO', entidad_federal='ZU' WHERE cedula='11325596102';
A66: 2025-2026 | B66: 1F | C66: B | D66: 011415053986 | E66: 45922 | F66: =IFERROR(VLOOKUP(TRIM($D66), Hoja4_2!$A$2:$L$10000, 4, 0), "Revisar") -> 41669 | G66: =IFERROR(VLOOKUP(TRIM($D66), Hoja4_2!$A$2:$L$10000, 5, 0), "Revisar") -> FEMENINO | H66: =IFERROR(VLOOKUP(TRIM($D66), Hoja4_2!$A$2:$L$10000, 7, 0), "Revisar") -> JESUS ENRIQUE LOSSADA | I66: =IFERROR(VLOOKUP(TRIM($D66), Hoja4_2!$A$2:$L$10000, 9, 0), "Revisar") -> ZU | J66: =IFERROR(VLOOKUP(TRIM($D66), Hoja4_2!$A$2:$L$10000, 12, 0), "Revisar") -> 15053986 | K66: =TEXT(TRIM(D66),"0") -> 11415053986 | L66: =IF(F66="Revisar","NULL",CONCATENATE("'",TEXT(F66,"yyyy-mm-dd"),"'")) -> '2014-01-30' | M66: =IF(G66="Revisar","NULL",CONCATENATE("'",MID(G66,1,1),"'")) -> 'F' | N66: =IF(H66="Revisar","NULL",CONCATENATE("'",H66,"'")) -> 'JESUS ENRIQUE LOSSADA' | O66: =IF(I66="Revisar","NULL",CONCATENATE("'",I66,"'")) -> 'ZU' | P66: ="UPDATE estudiantes SET fecha_nacimiento="&L66&", sexo="&M66&", lugar_nacimiento="&N66&", entidad_federal="&O66&" WHERE cedula='"&K66&"';" -> UPDATE estudiantes SET fecha_nacimiento='2014-01-30', sexo='F', lugar_nacimiento='JESUS ENRIQUE LOSSADA', entidad_federal='ZU' WHERE cedula='11415053986';
A67: 2025-2026 | B67: 1F | C67: B | D67: 011417938235 | E67: 45922 | F67: =IFERROR(VLOOKUP(TRIM($D67), Hoja4_2!$A$2:$L$10000, 4, 0), "Revisar") -> 41678 | G67: =IFERROR(VLOOKUP(TRIM($D67), Hoja4_2!$A$2:$L$10000, 5, 0), "Revisar") -> FEMENINO | H67: =IFERROR(VLOOKUP(TRIM($D67), Hoja4_2!$A$2:$L$10000, 7, 0), "Revisar") -> MARACAIBO | I67: =IFERROR(VLOOKUP(TRIM($D67), Hoja4_2!$A$2:$L$10000, 9, 0), "Revisar") -> ZU | J67: =IFERROR(VLOOKUP(TRIM($D67), Hoja4_2!$A$2:$L$10000, 12, 0), "Revisar") -> 17938235 | K67: =TEXT(TRIM(D67),"0") -> 11417938235 | L67: =IF(F67="Revisar","NULL",CONCATENATE("'",TEXT(F67,"yyyy-mm-dd"),"'")) -> '2014-02-08' | M67: =IF(G67="Revisar","NULL",CONCATENATE("'",MID(G67,1,1),"'")) -> 'F' | N67: =IF(H67="Revisar","NULL",CONCATENATE("'",H67,"'")) -> 'MARACAIBO' | O67: =IF(I67="Revisar","NULL",CONCATENATE("'",I67,"'")) -> 'ZU' | P67: ="UPDATE estudiantes SET fecha_nacimiento="&L67&", sexo="&M67&", lugar_nacimiento="&N67&", entidad_federal="&O67&" WHERE cedula='"&K67&"';" -> UPDATE estudiantes SET fecha_nacimiento='2014-02-08', sexo='F', lugar_nacimiento='MARACAIBO', entidad_federal='ZU' WHERE cedula='11417938235';
A68: 2025-2026 | B68: 1F | C68: B | D68: 011423466371 | E68: 45922 | F68: =IFERROR(VLOOKUP(TRIM($D68), Hoja4_2!$A$2:$L$10000, 4, 0), "Revisar") -> 41723 | G68: =IFERROR(VLOOKUP(TRIM($D68), Hoja4_2!$A$2:$L$10000, 5, 0), "Revisar") -> FEMENINO | H68: =IFERROR(VLOOKUP(TRIM($D68), Hoja4_2!$A$2:$L$10000, 7, 0), "Revisar") -> MARACAIBO | I68: =IFERROR(VLOOKUP(TRIM($D68), Hoja4_2!$A$2:$L$10000, 9, 0), "Revisar") -> ZU | J68: =IFERROR(VLOOKUP(TRIM($D68), Hoja4_2!$A$2:$L$10000, 12, 0), "Revisar") -> 09783701 | K68: =TEXT(TRIM(D68),"0") -> 11423466371 | L68: =IF(F68="Revisar","NULL",CONCATENATE("'",TEXT(F68,"yyyy-mm-dd"),"'")) -> '2014-03-25' | M68: =IF(G68="Revisar","NULL",CONCATENATE("'",MID(G68,1,1),"'")) -> 'F' | N68: =IF(H68="Revisar","NULL",CONCATENATE("'",H68,"'")) -> 'MARACAIBO' | O68: =IF(I68="Revisar","NULL",CONCATENATE("'",I68,"'")) -> 'ZU' | P68: ="UPDATE estudiantes SET fecha_nacimiento="&L68&", sexo="&M68&", lugar_nacimiento="&N68&", entidad_federal="&O68&" WHERE cedula='"&K68&"';" -> UPDATE estudiantes SET fecha_nacimiento='2014-03-25', sexo='F', lugar_nacimiento='MARACAIBO', entidad_federal='ZU' WHERE cedula='11423466371';
A69: 2025-2026 | B69: 1F | C69: B | D69: 011523466488 | E69: 45922 | F69: =IFERROR(VLOOKUP(TRIM($D69), Hoja4_2!$A$2:$L$10000, 4, 0), "Revisar") -> 42114 | G69: =IFERROR(VLOOKUP(TRIM($D69), Hoja4_2!$A$2:$L$10000, 5, 0), "Revisar") -> FEMENINO | H69: =IFERROR(VLOOKUP(TRIM($D69), Hoja4_2!$A$2:$L$10000, 7, 0), "Revisar") -> JESUS ENRIQUE LOSSADA | I69: =IFERROR(VLOOKUP(TRIM($D69), Hoja4_2!$A$2:$L$10000, 9, 0), "Revisar") -> ZU | J69: =IFERROR(VLOOKUP(TRIM($D69), Hoja4_2!$A$2:$L$10000, 12, 0), "Revisar") -> 23466488 | K69: =TEXT(TRIM(D69),"0") -> 11523466488 | L69: =IF(F69="Revisar","NULL",CONCATENATE("'",TEXT(F69,"yyyy-mm-dd"),"'")) -> '2015-04-20' | M69: =IF(G69="Revisar","NULL",CONCATENATE("'",MID(G69,1,1),"'")) -> 'F' | N69: =IF(H69="Revisar","NULL",CONCATENATE("'",H69,"'")) -> 'JESUS ENRIQUE LOSSADA' | O69: =IF(I69="Revisar","NULL",CONCATENATE("'",I69,"'")) -> 'ZU' | P69: ="UPDATE estudiantes SET fecha_nacimiento="&L69&", sexo="&M69&", lugar_nacimiento="&N69&", entidad_federal="&O69&" WHERE cedula='"&K69&"';" -> UPDATE estudiantes SET fecha_nacimiento='2015-04-20', sexo='F', lugar_nacimiento='JESUS ENRIQUE LOSSADA', entidad_federal='ZU' WHERE cedula='11523466488';
A70: 2025-2026 | B70: 1F | C70: B | D70: 011529645071 | E70: 45923 | F70: =IFERROR(VLOOKUP(TRIM($D70), Hoja4_2!$A$2:$L$10000, 4, 0), "Revisar") -> 42050 | G70: =IFERROR(VLOOKUP(TRIM($D70), Hoja4_2!$A$2:$L$10000, 5, 0), "Revisar") -> FEMENINO | H70: =IFERROR(VLOOKUP(TRIM($D70), Hoja4_2!$A$2:$L$10000, 7, 0), "Revisar") -> MARACAIBO | I70: =IFERROR(VLOOKUP(TRIM($D70), Hoja4_2!$A$2:$L$10000, 9, 0), "Revisar") -> ZU | J70: =IFERROR(VLOOKUP(TRIM($D70), Hoja4_2!$A$2:$L$10000, 12, 0), "Revisar") -> 29645071 | K70: =TEXT(TRIM(D70),"0") -> 11529645071 | L70: =IF(F70="Revisar","NULL",CONCATENATE("'",TEXT(F70,"yyyy-mm-dd"),"'")) -> '2015-02-15' | M70: =IF(G70="Revisar","NULL",CONCATENATE("'",MID(G70,1,1),"'")) -> 'F' | N70: =IF(H70="Revisar","NULL",CONCATENATE("'",H70,"'")) -> 'MARACAIBO' | O70: =IF(I70="Revisar","NULL",CONCATENATE("'",I70,"'")) -> 'ZU' | P70: ="UPDATE estudiantes SET fecha_nacimiento="&L70&", sexo="&M70&", lugar_nacimiento="&N70&", entidad_federal="&O70&" WHERE cedula='"&K70&"';" -> UPDATE estudiantes SET fecha_nacimiento='2015-02-15', sexo='F', lugar_nacimiento='MARACAIBO', entidad_federal='ZU' WHERE cedula='11529645071';
A71: 2025-2026 | B71: 1F | C71: C | D71: 000034760845 | E71: 45922 | F71: =IFERROR(VLOOKUP(TRIM($D71), Hoja4_2!$A$2:$L$10000, 4, 0), "Revisar") -> 41327 | G71: =IFERROR(VLOOKUP(TRIM($D71), Hoja4_2!$A$2:$L$10000, 5, 0), "Revisar") -> MASCULINO | H71: =IFERROR(VLOOKUP(TRIM($D71), Hoja4_2!$A$2:$L$10000, 7, 0), "Revisar") -> MARACAIBO | I71: =IFERROR(VLOOKUP(TRIM($D71), Hoja4_2!$A$2:$L$10000, 9, 0), "Revisar") -> ZU | J71: =IFERROR(VLOOKUP(TRIM($D71), Hoja4_2!$A$2:$L$10000, 12, 0), "Revisar") -> 15479103 | K71: =TEXT(TRIM(D71),"0") -> 34760845 | L71: =IF(F71="Revisar","NULL",CONCATENATE("'",TEXT(F71,"yyyy-mm-dd"),"'")) -> '2013-02-22' | M71: =IF(G71="Revisar","NULL",CONCATENATE("'",MID(G71,1,1),"'")) -> 'M' | N71: =IF(H71="Revisar","NULL",CONCATENATE("'",H71,"'")) -> 'MARACAIBO' | O71: =IF(I71="Revisar","NULL",CONCATENATE("'",I71,"'")) -> 'ZU' | P71: ="UPDATE estudiantes SET fecha_nacimiento="&L71&", sexo="&M71&", lugar_nacimiento="&N71&", entidad_federal="&O71&" WHERE cedula='"&K71&"';" -> UPDATE estudiantes SET fecha_nacimiento='2013-02-22', sexo='M', lugar_nacimiento='MARACAIBO', entidad_federal='ZU' WHERE cedula='34760845';
A72: 2025-2026 | B72: 1F | C72: C | D72: 000034835261 | E72: 45922 | F72: =IFERROR(VLOOKUP(TRIM($D72), Hoja4_2!$A$2:$L$10000, 4, 0), "Revisar") -> 40843 | G72: =IFERROR(VLOOKUP(TRIM($D72), Hoja4_2!$A$2:$L$10000, 5, 0), "Revisar") -> FEMENINO | H72: =IFERROR(VLOOKUP(TRIM($D72), Hoja4_2!$A$2:$L$10000, 7, 0), "Revisar") -> MARACAIBO | I72: =IFERROR(VLOOKUP(TRIM($D72), Hoja4_2!$A$2:$L$10000, 9, 0), "Revisar") -> ZU | J72: =IFERROR(VLOOKUP(TRIM($D72), Hoja4_2!$A$2:$L$10000, 12, 0), "Revisar") -> 17938287 | K72: =TEXT(TRIM(D72),"0") -> 34835261 | L72: =IF(F72="Revisar","NULL",CONCATENATE("'",TEXT(F72,"yyyy-mm-dd"),"'")) -> '2011-10-27' | M72: =IF(G72="Revisar","NULL",CONCATENATE("'",MID(G72,1,1),"'")) -> 'F' | N72: =IF(H72="Revisar","NULL",CONCATENATE("'",H72,"'")) -> 'MARACAIBO' | O72: =IF(I72="Revisar","NULL",CONCATENATE("'",I72,"'")) -> 'ZU' | P72: ="UPDATE estudiantes SET fecha_nacimiento="&L72&", sexo="&M72&", lugar_nacimiento="&N72&", entidad_federal="&O72&" WHERE cedula='"&K72&"';" -> UPDATE estudiantes SET fecha_nacimiento='2011-10-27', sexo='F', lugar_nacimiento='MARACAIBO', entidad_federal='ZU' WHERE cedula='34835261';
A73: 2025-2026 | B73: 1F | C73: C | D73: 000036070529 | E73: 45929 | F73: =IFERROR(VLOOKUP(TRIM($D73), Hoja4_2!$A$2:$L$10000, 4, 0), "Revisar") -> 41078 | G73: =IFERROR(VLOOKUP(TRIM($D73), Hoja4_2!$A$2:$L$10000, 5, 0), "Revisar") -> MASCULINO | H73: =IFERROR(VLOOKUP(TRIM($D73), Hoja4_2!$A$2:$L$10000, 7, 0), "Revisar") -> JESUS ENRIQUE LOSSADA | I73: =IFERROR(VLOOKUP(TRIM($D73), Hoja4_2!$A$2:$L$10000, 9, 0), "Revisar") -> ZU | J73: =IFERROR(VLOOKUP(TRIM($D73), Hoja4_2!$A$2:$L$10000, 12, 0), "Revisar") -> 07626287 | K73: =TEXT(TRIM(D73),"0") -> 36070529 | L73: =IF(F73="Revisar","NULL",CONCATENATE("'",TEXT(F73,"yyyy-mm-dd"),"'")) -> '2012-06-18' | M73: =IF(G73="Revisar","NULL",CONCATENATE("'",MID(G73,1,1),"'")) -> 'M' | N73: =IF(H73="Revisar","NULL",CONCATENATE("'",H73,"'")) -> 'JESUS ENRIQUE LOSSADA' | O73: =IF(I73="Revisar","NULL",CONCATENATE("'",I73,"'")) -> 'ZU' | P73: ="UPDATE estudiantes SET fecha_nacimiento="&L73&", sexo="&M73&", lugar_nacimiento="&N73&", entidad_federal="&O73&" WHERE cedula='"&K73&"';" -> UPDATE estudiantes SET fecha_nacimiento='2012-06-18', sexo='M', lugar_nacimiento='JESUS ENRIQUE LOSSADA', entidad_federal='ZU' WHERE cedula='36070529';
A74: 2025-2026 | B74: 1F | C74: C | D74: 000036228085 | E74: 45922 | F74: =IFERROR(VLOOKUP(TRIM($D74), Hoja4_2!$A$2:$L$10000, 4, 0), "Revisar") -> 41453 | G74: =IFERROR(VLOOKUP(TRIM($D74), Hoja4_2!$A$2:$L$10000, 5, 0), "Revisar") -> FEMENINO | H74: =IFERROR(VLOOKUP(TRIM($D74), Hoja4_2!$A$2:$L$10000, 7, 0), "Revisar") -> MARACAIBO | I74: =IFERROR(VLOOKUP(TRIM($D74), Hoja4_2!$A$2:$L$10000, 9, 0), "Revisar") -> ZU | J74: =IFERROR(VLOOKUP(TRIM($D74), Hoja4_2!$A$2:$L$10000, 12, 0), "Revisar") -> 09754394 | K74: =TEXT(TRIM(D74),"0") -> 36228085 | L74: =IF(F74="Revisar","NULL",CONCATENATE("'",TEXT(F74,"yyyy-mm-dd"),"'")) -> '2013-06-28' | M74: =IF(G74="Revisar","NULL",CONCATENATE("'",MID(G74,1,1),"'")) -> 'F' | N74: =IF(H74="Revisar","NULL",CONCATENATE("'",H74,"'")) -> 'MARACAIBO' | O74: =IF(I74="Revisar","NULL",CONCATENATE("'",I74,"'")) -> 'ZU' | P74: ="UPDATE estudiantes SET fecha_nacimiento="&L74&", sexo="&M74&", lugar_nacimiento="&N74&", entidad_federal="&O74&" WHERE cedula='"&K74&"';" -> UPDATE estudiantes SET fecha_nacimiento='2013-06-28', sexo='F', lugar_nacimiento='MARACAIBO', entidad_federal='ZU' WHERE cedula='36228085';
A75: 2025-2026 | B75: 1F | C75: C | D75: 000036292258 | E75: 45922 | F75: =IFERROR(VLOOKUP(TRIM($D75), Hoja4_2!$A$2:$L$10000, 4, 0), "Revisar") -> 41424 | G75: =IFERROR(VLOOKUP(TRIM($D75), Hoja4_2!$A$2:$L$10000, 5, 0), "Revisar") -> FEMENINO | H75: =IFERROR(VLOOKUP(TRIM($D75), Hoja4_2!$A$2:$L$10000, 7, 0), "Revisar") -> MARACAIBO | I75: =IFERROR(VLOOKUP(TRIM($D75), Hoja4_2!$A$2:$L$10000, 9, 0), "Revisar") -> ZU | J75: =IFERROR(VLOOKUP(TRIM($D75), Hoja4_2!$A$2:$L$10000, 12, 0), "Revisar") -> 20833989 | K75: =TEXT(TRIM(D75),"0") -> 36292258 | L75: =IF(F75="Revisar","NULL",CONCATENATE("'",TEXT(F75,"yyyy-mm-dd"),"'")) -> '2013-05-30' | M75: =IF(G75="Revisar","NULL",CONCATENATE("'",MID(G75,1,1),"'")) -> 'F' | N75: =IF(H75="Revisar","NULL",CONCATENATE("'",H75,"'")) -> 'MARACAIBO' | O75: =IF(I75="Revisar","NULL",CONCATENATE("'",I75,"'")) -> 'ZU' | P75: ="UPDATE estudiantes SET fecha_nacimiento="&L75&", sexo="&M75&", lugar_nacimiento="&N75&", entidad_federal="&O75&" WHERE cedula='"&K75&"';" -> UPDATE estudiantes SET fecha_nacimiento='2013-05-30', sexo='F', lugar_nacimiento='MARACAIBO', entidad_federal='ZU' WHERE cedula='36292258';
A76: 2025-2026 | B76: 1F | C76: C | D76: 000036345288 | E76: 45922 | F76: =IFERROR(VLOOKUP(TRIM($D76), Hoja4_2!$A$2:$L$10000, 4, 0), "Revisar") -> 41277 | G76: =IFERROR(VLOOKUP(TRIM($D76), Hoja4_2!$A$2:$L$10000, 5, 0), "Revisar") -> MASCULINO | H76: =IFERROR(VLOOKUP(TRIM($D76), Hoja4_2!$A$2:$L$10000, 7, 0), "Revisar") -> MARACAIBO | I76: =IFERROR(VLOOKUP(TRIM($D76), Hoja4_2!$A$2:$L$10000, 9, 0), "Revisar") -> ZU | J76: =IFERROR(VLOOKUP(TRIM($D76), Hoja4_2!$A$2:$L$10000, 12, 0), "Revisar") -> 16835698 | K76: =TEXT(TRIM(D76),"0") -> 36345288 | L76: =IF(F76="Revisar","NULL",CONCATENATE("'",TEXT(F76,"yyyy-mm-dd"),"'")) -> '2013-01-03' | M76: =IF(G76="Revisar","NULL",CONCATENATE("'",MID(G76,1,1),"'")) -> 'M' | N76: =IF(H76="Revisar","NULL",CONCATENATE("'",H76,"'")) -> 'MARACAIBO' | O76: =IF(I76="Revisar","NULL",CONCATENATE("'",I76,"'")) -> 'ZU' | P76: ="UPDATE estudiantes SET fecha_nacimiento="&L76&", sexo="&M76&", lugar_nacimiento="&N76&", entidad_federal="&O76&" WHERE cedula='"&K76&"';" -> UPDATE estudiantes SET fecha_nacimiento='2013-01-03', sexo='M', lugar_nacimiento='MARACAIBO', entidad_federal='ZU' WHERE cedula='36345288';
... A78: 2025-2026 | B78: 1F | C78: C | D78: 000036773562 | E78: 45922 | F78: =IFERROR(VLOOKUP(TRIM($D78), Hoja4_2!$A$2:$L$10000, 4, 0), "Revisar") -> 41954 | G78: =IFERROR(VLOOKUP(TRIM($D78), Hoja4_2!$A$2:$L$10000, 5, 0), "Revisar") -> FEMENINO | H78: =IFERROR(VLOOKUP(TRIM($D78), Hoja4_2!$A$2:$L$10000, 7, 0), "Revisar") -> MARACAIBO | I78: =IFERROR(VLOOKUP(TRIM($D78), Hoja4_2!$A$2:$L$10000, 9, 0), "Revisar") -> ZU | J78: =IFERROR(VLOOKUP(TRIM($D78), Hoja4_2!$A$2:$L$10000, 12, 0), "Revisar") -> 13081048 | K78: =TEXT(TRIM(D78),"0") -> 36773562 | L78: =IF(F78="Revisar","NULL",CONCATENATE("'",TEXT(F78,"yyyy-mm-dd"),"'")) -> '2014-11-11' | M78: =IF(G78="Revisar","NULL",CONCATENATE("'",MID(G78,1,1),"'")) -> 'F' | N78: =IF(H78="Revisar","NULL",CONCATENATE("'",H78,"'")) -> 'MARACAIBO' | O78: =IF(I78="Revisar","NULL",CONCATENATE("'",I78,"'")) -> 'ZU' | P78: ="UPDATE estudiantes SET fecha_nacimiento="&L78&", sexo="&M78&", lugar_nacimiento="&N78&", entidad_federal="&O78&" WHERE cedula='"&K78&"';" -> UPDATE estudiantes SET fecha_nacimiento='2014-11-11', sexo='F', lugar_nacimiento='MARACAIBO', entidad_federal='ZU' WHERE cedula='36773562';
A79: 2025-2026 | B79: 1F | C79: C | D79: 000036848161 | E79: 46043 | F79: NULL | G79: NULL | H79: NULL | I79: NULL | J79: NULL | K79: =TEXT(TRIM(D79),"0") -> 36848161 | L79: =IF(F79="Revisar","NULL",CONCATENATE("'",TEXT(F79,"yyyy-mm-dd"),"'")) -> 'NULL' | M79: =IF(G79="Revisar","NULL",CONCATENATE("'",MID(G79,1,1),"'")) -> 'N' | N79: =IF(H79="Revisar","NULL",CONCATENATE("'",H79,"'")) -> 'NULL' | O79: =IF(I79="Revisar","NULL",CONCATENATE("'",I79,"'")) -> 'NULL' | P79: ="UPDATE estudiantes SET fecha_nacimiento="&L79&", sexo="&M79&", lugar_nacimiento="&N79&", entidad_federal="&O79&" WHERE cedula='"&K79&"';" -> UPDATE estudiantes SET fecha_nacimiento='NULL', sexo='N', lugar_nacimiento='NULL', entidad_federal='NULL' WHERE cedula='36848161';
A80: 2025-2026 | B80: 1F | C80: C | D80: 000036864147 | E80: 45922 | F80: =IFERROR(VLOOKUP(TRIM($D80), Hoja4_2!$A$2:$L$10000, 4, 0), "Revisar") -> 41298 | G80: =IFERROR(VLOOKUP(TRIM($D80), Hoja4_2!$A$2:$L$10000, 5, 0), "Revisar") -> FEMENINO | H80: =IFERROR(VLOOKUP(TRIM($D80), Hoja4_2!$A$2:$L$10000, 7, 0), "Revisar") -> MARACAIBO | I80: =IFERROR(VLOOKUP(TRIM($D80), Hoja4_2!$A$2:$L$10000, 9, 0), "Revisar") -> ZU | J80: =IFERROR(VLOOKUP(TRIM($D80), Hoja4_2!$A$2:$L$10000, 12, 0), "Revisar") -> 20508742 | K80: =TEXT(TRIM(D80),"0") -> 36864147 | L80: =IF(F80="Revisar","NULL",CONCATENATE("'",TEXT(F80,"yyyy-mm-dd"),"'")) -> '2013-01-24' | M80: =IF(G80="Revisar","NULL",CONCATENATE("'",MID(G80,1,1),"'")) -> 'F' | N80: =IF(H80="Revisar","NULL",CONCATENATE("'",H80,"'")) -> 'MARACAIBO' | O80: =IF(I80="Revisar","NULL",CONCATENATE("'",I80,"'")) -> 'ZU' | P80: ="UPDATE estudiantes SET fecha_nacimiento="&L80&", sexo="&M80&", lugar_nacimiento="&N80&", entidad_federal="&O80&" WHERE cedula='"&K80&"';" -> UPDATE estudiantes SET fecha_nacimiento='2013-01-24', sexo='F', lugar_nacimiento='MARACAIBO', entidad_federal='ZU' WHERE cedula='36864147';
A81: 2025-2026 | B81: 1F | C81: C | D81: 000036907613 | E81: 45922 | F81: =IFERROR(VLOOKUP(TRIM($D81), Hoja4_2!$A$2:$L$10000, 4, 0), "Revisar") -> 41277 | G81: =IFERROR(VLOOKUP(TRIM($D81), Hoja4_2!$A$2:$L$10000, 5, 0), "Revisar") -> MASCULINO | H81: =IFERROR(VLOOKUP(TRIM($D81), Hoja4_2!$A$2:$L$10000, 7, 0), "Revisar") -> JESUS ENRIQUE LOSSADA | I81: =IFERROR(VLOOKUP(TRIM($D81), Hoja4_2!$A$2:$L$10000, 9, 0), "Revisar") -> ZU | J81: =IFERROR(VLOOKUP(TRIM($D81), Hoja4_2!$A$2:$L$10000, 12, 0), "Revisar") -> 20371881 | K81: =TEXT(TRIM(D81),"0") -> 36907613 | L81: =IF(F81="Revisar","NULL",CONCATENATE("'",TEXT(F81,"yyyy-mm-dd"),"'")) -> '2013-01-03' | M81: =IF(G81="Revisar","NULL",CONCATENATE("'",MID(G81,1,1),"'")) -> 'M' | N81: =IF(H81="Revisar","NULL",CONCATENATE("'",H81,"'")) -> 'JESUS ENRIQUE LOSSADA' | O81: =IF(I81="Revisar","NULL",CONCATENATE("'",I81,"'")) -> 'ZU' | P81: ="UPDATE estudiantes SET fecha_nacimiento="&L81&", sexo="&M81&", lugar_nacimiento="&N81&", entidad_federal="&O81&" WHERE cedula='"&K81&"';" -> UPDATE estudiantes SET fecha_nacimiento='2013-01-03', sexo='M', lugar_nacimiento='JESUS ENRIQUE LOSSADA', entidad_federal='ZU' WHERE cedula='36907613';
A82: 2025-2026 | B82: 1F | C82: C | D82: 000036988353 | E82: 45922 | F82: =IFERROR(VLOOKUP(TRIM($D82), Hoja4_2!$A$2:$L$10000, 4, 0), "Revisar") -> 41449 | G82: =IFERROR(VLOOKUP(TRIM($D82), Hoja4_2!$A$2:$L$10000, 5, 0), "Revisar") -> FEMENINO | H82: =IFERROR(VLOOKUP(TRIM($D82), Hoja4_2!$A$2:$L$10000, 7, 0), "Revisar") -> MARACAIBO | I82: =IFERROR(VLOOKUP(TRIM($D82), Hoja4_2!$A$2:$L$10000, 9, 0), "Revisar") -> ZU | J82: =IFERROR(VLOOKUP(TRIM($D82), Hoja4_2!$A$2:$L$10000, 12, 0), "Revisar") -> 20058317 | K82: =TEXT(TRIM(D82),"0") -> 36988353 | L82: =IF(F82="Revisar","NULL",CONCATENATE("'",TEXT(F82,"yyyy-mm-dd"),"'")) -> '2013-06-24' | M82: =IF(G82="Revisar","NULL",CONCATENATE("'",MID(G82,1,1),"'")) -> 'F' | N82: =IF(H82="Revisar","NULL",CONCATENATE("'",H82,"'")) -> 'MARACAIBO' | O82: =IF(I82="Revisar","NULL",CONCATENATE("'",I82,"'")) -> 'ZU' | P82: ="UPDATE estudiantes SET fecha_nacimiento="&L82&", sexo="&M82&", lugar_nacimiento="&N82&", entidad_federal="&O82&" WHERE cedula='"&K82&"';" -> UPDATE estudiantes SET fecha_nacimiento='2013-06-24', sexo='F', lugar_nacimiento='MARACAIBO', entidad_federal='ZU' WHERE cedula='36988353';
A83: 2025-2026 | B83: 1F | C83: C | D83: 000037007137 | E83: 45987 | F83: =IFERROR(VLOOKUP(TRIM($D83), Hoja4_2!$A$2:$L$10000, 4, 0), "Revisar") -> 41655 | G83: =IFERROR(VLOOKUP(TRIM($D83), Hoja4_2!$A$2:$L$10000, 5, 0), "Revisar") -> FEMENINO | H83: =IFERROR(VLOOKUP(TRIM($D83), Hoja4_2!$A$2:$L$10000, 7, 0), "Revisar") -> MARACAIBO | I83: =IFERROR(VLOOKUP(TRIM($D83), Hoja4_2!$A$2:$L$10000, 9, 0), "Revisar") -> ZU | J83: =IFERROR(VLOOKUP(TRIM($D83), Hoja4_2!$A$2:$L$10000, 12, 0), "Revisar") -> 18662051 | K83: =TEXT(TRIM(D83),"0") -> 37007137 | L83: =IF(F83="Revisar","NULL",CONCATENATE("'",TEXT(F83,"yyyy-mm-dd"),"'")) -> '2014-01-16' | M83: =IF(G83="Revisar","NULL",CONCATENATE("'",MID(G83,1,1),"'")) -> 'F' | N83: =IF(H83="Revisar","NULL",CONCATENATE("'",H83,"'")) -> 'MARACAIBO' | O83: =IF(I83="Revisar","NULL",CONCATENATE("'",I83,"'")) -> 'ZU' | P83: ="UPDATE estudiantes SET fecha_nacimiento="&L83&", sexo="&M83&", lugar_nacimiento="&N83&", entidad_federal="&O83&" WHERE cedula='"&K83&"';" -> UPDATE estudiantes SET fecha_nacimiento='2014-01-16', sexo='F', lugar_nacimiento='MARACAIBO', entidad_federal='ZU' WHERE cedula='37007137';
A84: 2025-2026 | B84: 1F | C84: C | D84: 000037029917 | E84: 45922 | F84: =IFERROR(VLOOKUP(TRIM($D84), Hoja4_2!$A$2:$L$10000, 4, 0), "Revisar") -> 41693 | G84: =IFERROR(VLOOKUP(TRIM($D84), Hoja4_2!$A$2:$L$10000, 5, 0), "Revisar") -> MASCULINO | H84: =IFERROR(VLOOKUP(TRIM($D84), Hoja4_2!$A$2:$L$10000, 7, 0), "Revisar") -> MARACAIBO | I84: =IFERROR(VLOOKUP(TRIM($D84), Hoja4_2!$A$2:$L$10000, 9, 0), "Revisar") -> ZU | J84: =IFERROR(VLOOKUP(TRIM($D84), Hoja4_2!$A$2:$L$10000, 12, 0), "Revisar") -> 25979267 | K84: =TEXT(TRIM(D84),"0") -> 37029917 | L84: =IF(F84="Revisar","NULL",CONCATENATE("'",TEXT(F84,"yyyy-mm-dd"),"'")) -> '2014-02-23' | M84: =IF(G84="Revisar","NULL",CONCATENATE("'",MID(G84,1,1),"'")) -> 'M' | N84: =IF(H84="Revisar","NULL",CONCATENATE("'",H84,"'")) -> 'MARACAIBO' | O84: =IF(I84="Revisar","NULL",CONCATENATE("'",I84,"'")) -> 'ZU' | P84: ="UPDATE estudiantes SET fecha_nacimiento="&L84&", sexo="&M84&", lugar_nacimiento="&N84&", entidad_federal="&O84&" WHERE cedula='"&K84&"';" -> UPDATE estudiantes SET fecha_nacimiento='2014-02-23', sexo='M', lugar_nacimiento='MARACAIBO', entidad_federal='ZU' WHERE cedula='37029917';
A85: 2025-2026 | B85: 1F | C85: C | D85: 000037030009 | E85: 45922 | F85: =IFERROR(VLOOKUP(TRIM($D85), Hoja4_2!$A$2:$L$10000, 4, 0), "Revisar") -> 41693 | G85: =IFERROR(VLOOKUP(TRIM($D85), Hoja4_2!$A$2:$L$10000, 5, 0), "Revisar") -> FEMENINO | H85: =IFERROR(VLOOKUP(TRIM($D85), Hoja4_2!$A$2:$L$10000, 7, 0), "Revisar") -> MARACAIBO | I85: =IFERROR(VLOOKUP(TRIM($D85), Hoja4_2!$A$2:$L$10000, 9, 0), "Revisar") -> ZU | J85: =IFERROR(VLOOKUP(TRIM($D85), Hoja4_2!$A$2:$L$10000, 12, 0), "Revisar") -> 25979267 | K85: =TEXT(TRIM(D85),"0") -> 37030009 | L85: =IF(F85="Revisar","NULL",CONCATENATE("'",TEXT(F85,"yyyy-mm-dd"),"'")) -> '2014-02-23' | M85: =IF(G85="Revisar","NULL",CONCATENATE("'",MID(G85,1,1),"'")) -> 'F' | N85: =IF(H85="Revisar","NULL",CONCATENATE("'",H85,"'")) -> 'MARACAIBO' | O85: =IF(I85="Revisar","NULL",CONCATENATE("'",I85,"'")) -> 'ZU' | P85: ="UPDATE estudiantes SET fecha_nacimiento="&L85&", sexo="&M85&", lugar_nacimiento="&N85&", entidad_federal="&O85&" WHERE cedula='"&K85&"';" -> UPDATE estudiantes SET fecha_nacimiento='2014-02-23', sexo='F', lugar_nacimiento='MARACAIBO', entidad_federal='ZU' WHERE cedula='37030009';
A86: 2025-2026 | B86: 1F | C86: C | D86: 000037107700 | E86: 45922 | F86: =IFERROR(VLOOKUP(TRIM($D86), Hoja4_2!$A$2:$L$10000, 4, 0), "Revisar") -> 42034 | G86: =IFERROR(VLOOKUP(TRIM($D86), Hoja4_2!$A$2:$L$10000, 5, 0), "Revisar") -> FEMENINO | H86: =IFERROR(VLOOKUP(TRIM($D86), Hoja4_2!$A$2:$L$10000, 7, 0), "Revisar") -> MARACAIBO | I86: =IFERROR(VLOOKUP(TRIM($D86), Hoja4_2!$A$2:$L$10000, 9, 0), "Revisar") -> ZU | J86: =IFERROR(VLOOKUP(TRIM($D86), Hoja4_2!$A$2:$L$10000, 12, 0), "Revisar") -> 17833718 | K86: =TEXT(TRIM(D86),"0") -> 37107700 | L86: =IF(F86="Revisar","NULL",CONCATENATE("'",TEXT(F86,"yyyy-mm-dd"),"'")) -> '2015-01-30' | M86: =IF(G86="Revisar","NULL",CONCATENATE("'",MID(G86,1,1),"'")) -> 'F' | N86: =IF(H86="Revisar","NULL",CONCATENATE("'",H86,"'")) -> 'MARACAIBO' | O86: =IF(I86="Revisar","NULL",CONCATENATE("'",I86,"'")) -> 'ZU' | P86: ="UPDATE estudiantes SET fecha_nacimiento="&L86&", sexo="&M86&", lugar_nacimiento="&N86&", entidad_federal="&O86&" WHERE cedula='"&K86&"';" -> UPDATE estudiantes SET fecha_nacimiento='2015-01-30', sexo='F', lugar_nacimiento='MARACAIBO', entidad_federal='ZU' WHERE cedula='37107700';
A87: 2025-2026 | B87: 1F | C87: C | D87: 000037266329 | E87: 45922 | F87: =IFERROR(VLOOKUP(TRIM($D87), Hoja4_2!$A$2:$L$10000, 4, 0), "Revisar") -> 41619 | G87: =IFERROR(VLOOKUP(TRIM($D87), Hoja4_2!$A$2:$L$10000, 5, 0), "Revisar") -> FEMENINO | H87: =IFERROR(VLOOKUP(TRIM($D87), Hoja4_2!$A$2:$L$10000, 7, 0), "Revisar") -> MARACAIBO | I87: =IFERROR(VLOOKUP(TRIM($D87), Hoja4_2!$A$2:$L$10000, 9, 0), "Revisar") -> ZU | J87: =IFERROR(VLOOKUP(TRIM($D87), Hoja4_2!$A$2:$L$10000, 12, 0), "Revisar") -> 25439260 | K87: =TEXT(TRIM(D87),"0") -> 37266329 | L87: =IF(F87="Revisar","NULL",CONCATENATE("'",TEXT(F87,"yyyy-mm-dd"),"'")) -> '2013-12-11' | M87: =IF(G87="Revisar","NULL",CONCATENATE("'",MID(G87,1,1),"'")) -> 'F' | N87: =IF(H87="Revisar","NULL",CONCATENATE("'",H87,"'")) -> 'MARACAIBO' | O87: =IF(I87="Revisar","NULL",CONCATENATE("'",I87,"'")) -> 'ZU' | P87: ="UPDATE estudiantes SET fecha_nacimiento="&L87&", sexo="&M87&", lugar_nacimiento="&N87&", entidad_federal="&O87&" WHERE cedula='"&K87&"';" -> UPDATE estudiantes SET fecha_nacimiento='2013-12-11', sexo='F', lugar_nacimiento='MARACAIBO', entidad_federal='ZU' WHERE cedula='37266329';
A88: 2025-2026 | B88: 1F | C88: C | D88: 011216687079 | E88: 45922 | F88: =IFERROR(VLOOKUP(TRIM($D88), Hoja4_2!$A$2:$L$10000, 4, 0), "Revisar") -> 41159 | G88: =IFERROR(VLOOKUP(TRIM($D88), Hoja4_2!$A$2:$L$10000, 5, 0), "Revisar") -> FEMENINO | H88: =IFERROR(VLOOKUP(TRIM($D88), Hoja4_2!$A$2:$L$10000, 7, 0), "Revisar") -> MARACAIBO | I88: =IFERROR(VLOOKUP(TRIM($D88), Hoja4_2!$A$2:$L$10000, 9, 0), "Revisar") -> ZU | J88: =IFERROR(VLOOKUP(TRIM($D88), Hoja4_2!$A$2:$L$10000, 12, 0), "Revisar") -> 16687079 | K88: =TEXT(TRIM(D88),"0") -> 11216687079 | L88: =IF(F88="Revisar","NULL",CONCATENATE("'",TEXT(F88,"yyyy-mm-dd"),"'")) -> '2012-09-07' | M88: =IF(G88="Revisar","NULL",CONCATENATE("'",MID(G88,1,1),"'")) -> 'F' | N88: =IF(H88="Revisar","NULL",CONCATENATE("'",H88,"'")) -> 'MARACAIBO' | O88: =IF(I88="Revisar","NULL",CONCATENATE("'",I88,"'")) -> 'ZU' | P88: ="UPDATE estudiantes SET fecha_nacimiento="&L88&", sexo="&M88&", lugar_nacimiento="&N88&", entidad_federal="&O88&" WHERE cedula='"&K88&"';" -> UPDATE estudiantes SET fecha_nacimiento='2012-09-07', sexo='F', lugar_nacimiento='MARACAIBO', entidad_federal='ZU' WHERE cedula='11216687079';
A89: 2025-2026 | B89: 1F | C89: C | D89: 011217087302 | E89: 45922 | F89: =IFERROR(VLOOKUP(TRIM($D89), Hoja4_2!$A$2:$L$10000, 4, 0), "Revisar") -> 41102 | G89: =IFERROR(VLOOKUP(TRIM($D89), Hoja4_2!$A$2:$L$10000, 5, 0), "Revisar") -> MASCULINO | H89: =IFERROR(VLOOKUP(TRIM($D89), Hoja4_2!$A$2:$L$10000, 7, 0), "Revisar") -> MARACAIBO | I89: =IFERROR(VLOOKUP(TRIM($D89), Hoja4_2!$A$2:$L$10000, 9, 0), "Revisar") -> ZU | J89: =IFERROR(VLOOKUP(TRIM($D89), Hoja4_2!$A$2:$L$10000, 12, 0), "Revisar") -> 17087302 | K89: =TEXT(TRIM(D89),"0") -> 11217087302 | L89: =IF(F89="Revisar","NULL",CONCATENATE("'",TEXT(F89,"yyyy-mm-dd"),"'")) -> '2012-07-12' | M89: =IF(G89="Revisar","NULL",CONCATENATE("'",MID(G89,1,1),"'")) -> 'M' | N89: =IF(H89="Revisar","NULL",CONCATENATE("'",H89,"'")) -> 'MARACAIBO' | O89: =IF(I89="Revisar","NULL",CONCATENATE("'",I89,"'")) -> 'ZU' | P89: ="UPDATE estudiantes SET fecha_nacimiento="&L89&", sexo="&M89&", lugar_nacimiento="&N89&", entidad_federal="&O89&" WHERE cedula='"&K89&"';" -> UPDATE estudiantes SET fecha_nacimiento='2012-07-12', sexo='M', lugar_nacimiento='MARACAIBO', entidad_federal='ZU' WHERE cedula='11217087302';
A90: 2025-2026 | B90: 1F | C90: C | D90: 011220686019 | E90: 45922 | F90: =IFERROR(VLOOKUP(TRIM($D90), Hoja4_2!$A$2:$L$10000, 4, 0), "Revisar") -> 41235 | G90: =IFERROR(VLOOKUP(TRIM($D90), Hoja4_2!$A$2:$L$10000, 5, 0), "Revisar") -> FEMENINO | H90: =IFERROR(VLOOKUP(TRIM($D90), Hoja4_2!$A$2:$L$10000, 7, 0), "Revisar") -> MARACAIBO | I90: =IFERROR(VLOOKUP(TRIM($D90), Hoja4_2!$A$2:$L$10000, 9, 0), "Revisar") -> ZU | J90: =IFERROR(VLOOKUP(TRIM($D90), Hoja4_2!$A$2:$L$10000, 12, 0), "Revisar") -> 20686019 | K90: =TEXT(TRIM(D90),"0") -> 11220686019 | L90: =IF(F90="Revisar","NULL",CONCATENATE("'",TEXT(F90,"yyyy-mm-dd"),"'")) -> '2012-11-22' | M90: =IF(G90="Revisar","NULL",CONCATENATE("'",MID(G90,1,1),"'")) -> 'F' | N90: =IF(H90="Revisar","NULL",CONCATENATE("'",H90,"'")) -> 'MARACAIBO' | O90: =IF(I90="Revisar","NULL",CONCATENATE("'",I90,"'")) -> 'ZU' | P90: ="UPDATE estudiantes SET fecha_nacimiento="&L90&", sexo="&M90&", lugar_nacimiento="&N90&", entidad_federal="&O90&" WHERE cedula='"&K90&"';" -> UPDATE estudiantes SET fecha_nacimiento='2012-11-22', sexo='F', lugar_nacimiento='MARACAIBO', entidad_federal='ZU' WHERE cedula='11220686019';
...

Sheet Hoja4_2
A1: CedAlu | B1: NomAlu | C1: ApeAlu | D1: FchNac | E1: SexAlu | F1: NacAlu | G1: LugNac | H1: Estado | I1: EntFed | J1: Direccion | K1: Telefono | L1: CedRpr | M1: PaisNa
A2: 000023466358 | B2: ALEX MIGUEL | C2: FARIA TORRES | D2: 34717 | E2: MASCULINO | F2: VENEZOLANO | G2: MARACAIBO | H2: ZULIA | I2: ZU | J2: CAMPO COQUIVACOA | K2: * | L2: 21509183 | M2: VENEZUELA | P2: =IFERROR(VLOOKUP(TRIM($D2), Hoja4_2!$A$2:$L$10000, 4, 0), "Revisar") -> Revisar
A3: 000023769464 | B3: ALEXANDER RAMON | C3: SILVA ARPUSSHANA | D3: 34751 | E3: MASCULINO | F3: VENEZOLANO | G3: JESUS ENRIQUE LOSSADA | H3: ZULIA | I3: ZU | J3: S/ EL LABERINTO | K3: 0412-6497504 | L3: 12697341 | M3: VENEZUELA
A4: 000024413243 | B4: LUIS ALEJANDRO | C4: ESPINA URDANETA | D4: 35010 | E4: MASCULINO | F4: VENEZOLANO | G4: MARACAIBO | H4: ZULIA | I4: ZU | J4: AV. PRINCIPAL LA PAZ | K4: * | L4: 17088450 | M4: VENEZUELA
A5: 000025342414 | B5: NADITH JOSE | C5: ATENCIO NAVA | D5: 35326 | E5: MASCULINO | F5: VENEZOLANO | G5: JESUS ENRIQUE LOSSADA | H5: ZULIA | I5: ZU | J5: CIUDAD COMUNAL EL LAB. | K5: 0416-0617240 | L5: 12443385 | M5: VENEZUELA
A6: 000025439229 | B6: LEANDRO JOSE | C6: URDANETA URDANETA | D6: 35140 | E6: MASCULINO | F6: VENEZOLANO | G6: MARACAIBO | H6: ZULIA | I6: ZU | J6: LA CONQUISTA | K6: * | L6: 13005218 | M6: VENEZUELA
A7: 000025439252 | B7: JHONY GEL | C7: REYES RINCON | D7: 35440 | E7: MASCULINO | F7: VENEZOLANO | G7: JESUS ENRIQUE LOSSADA | H7: ZULIA | I7: ZU | J7: B/ MARIO URDANETA | K7: 0416-2242199 | L7: 10429013 | M7: VENEZUELA
A8: 000025439255 | B8: JHOENDRY JESUS | C8: GONZALEZ GONZALEZ | D8: 35499 | E8: MASCULINO | F8: VENEZOLANO | G8: MARACAIBO | H8: ZULIA | I8: ZU | J8: SECTOR 115 | K8: 0416-0180696 | L8: 09702102 | M8: VENEZUELA
A9: 000028558574 | B9: JOHAN DAVID | C9: CASTILLO VILLALOBOS | D9: 37245 | E9: MASCULINO | F9: VENEZOLANO | G9: MARACAIBO | H9: ZULIA | I9: ZU | J9: SECTOR VILLAS SALAS | K9: 0416-2623361 | L9: 16016439 | M9: VENEZUELA
A10: 000025596484 | B10: GIBELYS DEL CARMEN | C10: BRACHO GONZALEZ | D10: 35212 | E10: FEMENINO | F10: VENEZOLANO | G10: JESUS ENRIQUE LOSSADA | H10: ZULIA | I10: ZU | J10: S/ PARADA DE LOS BUSES | K10: * | L10: 13428543 | M10: VENEZUELA
A11: 000025680343 | B11: GUSTAVO ALBERTO | C11: ATENCIO NUÑEZ | D11: 35263 | E11: MASCULINO | F11: VENEZOLANO | G11: JESUS ENRIQUE LOSSADA | H11: ZULIA | I11: ZU | J11: S/ EL NAZARENO | K11: 0416-3618417 | L11: 09741221 | M11: VENEZUELA
A12: 000025763020 | B12: FABIAN RICARDO | C12: ROMERO MONTIEL | D12: 35398 | E12: MASCULINO | F12: VENEZOLANO | G12: MARA | H12: ZULIA | I12: ZU | J12: * | K12: * | L12: 21490627 | M12: VENEZUELA
A13: 000025883046 | B13: ANGEL RENE | C13: FERRER VARGAS | D13: 35691 | E13: MASCULINO | F13: VENEZOLANO | G13: MARACAIBO | H13: ZULIA | I13: ZU | J13: S/ ROBERTO FUENMAYOR | K13: 0416-2250558 | L13: 22163806 | M13: VENEZUELA
A14: 000025883047 | B14: BRAYAN JOSE | C14: HERRERA PADILLA | D14: 35232 | E14: MASCULINO | F14: VENEZOLANO | G14: MARACAIBO | H14: ZULIA | I14: ZU | J14: S/ ROBERTO FUENMAYOR | K14: * | L14: 21421748 | M14: VENEZUELA
... A4448: 000013627108 | B4448: WILLIAN ALBERTO | C4448: URDANETA URDANETA | D4448: 27259 | E4448: MASCULINO | F4448: VENEZOLANO | G4448: MARACAIBO | H4448: ZULIA | I4448: ZU | J4448: **** | K4448: * | L4448: 16298584 | M4448: VENEZUELA
